Workbook

Sheet Portada

Sheet RESUMEN 
A2: Cuadro 01 | W2: Enero
A3: INMATRICULACION DE VEHICULOS PESADOS, SEGÚN CLASE DE VEHICULO
A4: CLASE | B4: 45658 | C4: 45689 | D4: 45717 | E4: 45748 | F4: 45778 | G4: 45809 | H4: 45839 | I4: 45870 | J4: 45901 | K4: 45931 | L4: 45962 | M4: 45992 | N4: % PART.MES | O4: ACUMULADO 2025 | P4: % Part ACUM 2025 | R4: 45292 | S4: 45627 | T4: Var. % Ene '25 vs Dic '24 | U4: Var. % Ene '25 vs Ene '24 | W4: ACUMULADO 2024 | X4: Var. % ACUM 25/24
A5: CAMIONES | B5: 1191 | N5: =IFERROR(+B5/$B$8,"-") -> 0.62585391 | O5: =SUM(B5:M5) -> 1191 | P5: =+O5/$O$8 -> 0.62585391 | R5: 1050 | S5: 1020 | T5: =+IFERROR(B5/S5-1,"-") -> 0.16764706 | U5: =+IFERROR(B5/R5-1,"-") -> 0.13428571 | W5: 1050 | X5: =IFERROR(O5/W5-1,"-") -> 0.13428571
A6: MINIBUS,OMNIBUS | B6: 340 | N6: =IFERROR(+B6/$B$8,"-") -> 0.17866527 | O6: =SUM(B6:M6) -> 340 | P6: =+O6/$O$8 -> 0.17866527 | R6: 191 | S6: 298 | T6: =+IFERROR(B6/S6-1,"-") -> 0.1409396 | U6: =+IFERROR(B6/R6-1,"-") -> 0.78010471 | W6: 191 | X6: =IFERROR(O6/W6-1,"-") -> 0.78010471
A7: TRACTOCAMIONES | B7: 372 | N7: =IFERROR(+B7/$B$8,"-") -> 0.19548082 | O7: =SUM(B7:M7) -> 372 | P7: =+O7/$O$8 -> 0.19548082 | R7: 254 | S7: 253 | T7: =+IFERROR(B7/S7-1,"-") -> 0.47035573 | U7: =+IFERROR(B7/R7-1,"-") -> 0.46456693 | W7: 254 | X7: =IFERROR(O7/W7-1,"-") -> 0.46456693
A8: Total general | B8: =+B5+B6+B7 -> 1903 | C8: =+C5+C6+C7 -> 0 | D8: =+D5+D6+D7 -> 0 | E8: =+E5+E6+E7 -> 0 | F8: =+F5+F6+F7 -> 0 | G8: =+G5+G6+G7 -> 0 | H8: =+H5+H6+H7 -> 0 | I8: =+I5+I6+I7 -> 0 | ... M8: =+M5+M6+M7 -> 0 | N8: =SUM(N5:N7) -> 1 | O8: =+O5+O6+O7 -> 1903 | P8: =SUM(P5:P7) -> 1 | R8: =+R5+R6+R7 -> 1495 | S8: =+S5+S6+S7 -> 1571 | T8: =+IFERROR(B8/S8-1,"-") -> 0.21133036 | U8: =+IFERROR(B8/R8-1,"-") -> 0.2729097 | W8: =+W5+W6+W7 -> 1495 | X8: =IFERROR(O8/W8-1,"-") -> 0.2729097
A10: Elaboracion/Fuente : AAP - SUNARP
A12: Cuadro 02 | W12: =+W2 -> Enero
A13: INMATRICULACION DE VEHICULOS PESADOS, SEGÚN OFICINA REGISTRAL
A14: OFICINA | B14: =B4 -> 45658 | C14: =C4 -> 45689 | D14: =D4 -> 45717 | E14: =E4 -> 45748 | F14: =F4 -> 45778 | G14: =G4 -> 45809 | H14: =H4 -> 45839 | I14: =I4 -> 45870 | ... M14: =M4 -> 45992 | N14: % PART.MES | O14: =O4 -> ACUMULADO 2025 | P14: =P4 -> % Part ACUM 2025 | R14: =+R4 -> 45292 | S14: =+S4 -> 45627 | T14: =T4 -> Var. % Ene '25 vs Dic '24 | U14: =U4 -> Var. % Ene '25 vs Ene '24 | W14: =W4 -> ACUMULADO 2024 | X14: =X4 -> Var. % ACUM 25/24
A15: LIMA | B15: 1302 | N15: =IFERROR(+B15/$B$36,"-") -> 0.68418287 | O15: =SUM(B15:M15) -> 1302 | P15: =+O15/$O$36 -> 0.68418287 | R15: 1080 | S15: 1076 | T15: =+IFERROR(B15/S15-1,"-") -> 0.21003717 | U15: =+IFERROR(B15/R15-1,"-") -> 0.20555556 | W15: 1080 | X15: =IFERROR(O15/W15-1,"-") -> 0.20555556
A16: AREQUIPA | B16: 220 | N16: =IFERROR(+B16/$B$36,"-") -> 0.11560694 | O16: =SUM(B16:M16) -> 220 | P16: =+O16/$O$36 -> 0.11560694 | R16: 153 | S16: 197 | T16: =+IFERROR(B16/S16-1,"-") -> 0.11675127 | U16: =+IFERROR(B16/R16-1,"-") -> 0.4379085 | W16: 153 | X16: =IFERROR(O16/W16-1,"-") -> 0.4379085
A17: TRUJILLO | B17: 129 | N17: =IFERROR(+B17/$B$36,"-") -> 0.067787704 | O17: =SUM(B17:M17) -> 129 | P17: =+O17/$O$36 -> 0.067787704 | R17: 101 | S17: 89 | T17: =+IFERROR(B17/S17-1,"-") -> 0.4494382 | U17: =+IFERROR(B17/R17-1,"-") -> 0.27722772 | W17: 101 | X17: =IFERROR(O17/W17-1,"-") -> 0.27722772
A18: CUSCO | B18: 71 | N18: =IFERROR(+B18/$B$36,"-") -> 0.037309511 | O18: =SUM(B18:M18) -> 71 | P18: =+O18/$O$36 -> 0.037309511 | R18: 34 | S18: 29 | T18: =+IFERROR(B18/S18-1,"-") -> 1.4482759 | U18: =+IFERROR(B18/R18-1,"-") -> 1.0882353 | W18: 34 | X18: =IFERROR(O18/W18-1,"-") -> 1.0882353
A19: HUANCAYO | B19: 35 | N19: =IFERROR(+B19/$B$36,"-") -> 0.018392013 | O19: =SUM(B19:M19) -> 35 | P19: =+O19/$O$36 -> 0.018392013 | R19: 20 | S19: 16 | T19: =+IFERROR(B19/S19-1,"-") -> 1.1875 | U19: =+IFERROR(B19/R19-1,"-") -> 0.75 | W19: 20 | X19: =IFERROR(O19/W19-1,"-") -> 0.75
A20: TACNA | B20: 31 | N20: =IFERROR(+B20/$B$36,"-") -> 0.016290068 | O20: =SUM(B20:M20) -> 31 | P20: =+O20/$O$36 -> 0.016290068 | R20: 18 | S20: 13 | T20: =+IFERROR(B20/S20-1,"-") -> 1.3846154 | U20: =+IFERROR(B20/R20-1,"-") -> 0.72222222 | W20: 18 | X20: =IFERROR(O20/W20-1,"-") -> 0.72222222
A21: CHICLAYO | B21: 30 | N21: =IFERROR(+B21/$B$36,"-") -> 0.015764582 | O21: =SUM(B21:M21) -> 30 | P21: =+O21/$O$36 -> 0.015764582 | R21: 15 | S21: 47 | T21: =+IFERROR(B21/S21-1,"-") -> -0.36170213 | U21: =+IFERROR(B21/R21-1,"-") -> 1 | W21: 15 | X21: =IFERROR(O21/W21-1,"-") -> 1
A22: PIURA | B22: 18 | N22: =IFERROR(+B22/$B$36,"-") -> 0.0094587493 | O22: =SUM(B22:M22) -> 18 | P22: =+O22/$O$36 -> 0.0094587493 | R22: 11 | S22: 25 | T22: =+IFERROR(B22/S22-1,"-") -> -0.28 | U22: =+IFERROR(B22/R22-1,"-") -> 0.63636364 | W22: 11 | X22: =IFERROR(O22/W22-1,"-") -> 0.63636364
A23: JULIACA | B23: 17 | N23: =IFERROR(+B23/$B$36,"-") -> 0.0089332633 | O23: =SUM(B23:M23) -> 17 | P23: =+O23/$O$36 -> 0.0089332633 | R23: 12 | S23: 21 | T23: =+IFERROR(B23/S23-1,"-") -> -0.19047619 | U23: =+IFERROR(B23/R23-1,"-") -> 0.41666667 | W23: 12 | X23: =IFERROR(O23/W23-1,"-") -> 0.41666667
A24: CAJAMARCA | B24: 16 | N24: =IFERROR(+B24/$B$36,"-") -> 0.0084077772 | O24: =SUM(B24:M24) -> 16 | P24: =+O24/$O$36 -> 0.0084077772 | R24: 19 | S24: 23 | T24: =+IFERROR(B24/S24-1,"-") -> -0.30434783 | U24: =+IFERROR(B24/R24-1,"-") -> -0.15789474 | W24: 19 | X24: =IFERROR(O24/W24-1,"-") -> -0.15789474
A25: HUANUCO | B25: 13 | N25: =IFERROR(+B25/$B$36,"-") -> 0.006831319 | O25: =SUM(B25:M25) -> 13 | P25: =+O25/$O$36 -> 0.006831319 | R25: 4 | S25: 13 | T25: =+IFERROR(B25/S25-1,"-") -> 0 | U25: =+IFERROR(B25/R25-1,"-") -> 2.25 | W25: 4 | X25: =IFERROR(O25/W25-1,"-") -> 2.25
A26: TARAPOTO | B26: 7 | N26: =IFERROR(+B26/$B$36,"-") -> 0.0036784025 | O26: =SUM(B26:M26) -> 7 | P26: =+O26/$O$36 -> 0.0036784025 | R26: 3 | S26: 7 | T26: =+IFERROR(B26/S26-1,"-") -> 0 | U26: =+IFERROR(B26/R26-1,"-") -> 1.3333333 | W26: 3 | X26: =IFERROR(O26/W26-1,"-") -> 1.3333333
... A35: PUNO | B35: 0 | N35: =IFERROR(+B35/$B$36,"-") -> 0 | O35: =SUM(B35:M35) -> 0 | P35: =+O35/$O$36 -> 0 | R35: 1 | S35: 0 | T35: =+IFERROR(B35/S35-1,"-") -> - | U35: =+IFERROR(B35/R35-1,"-") -> -1 | W35: 1 | X35: =IFERROR(O35/W35-1,"-") -> -1
A36: TOTAL | B36: =SUM(B15:B35) -> 1903 | C36: =SUM(C15:C35) -> 0 | D36: =SUM(D15:D35) -> 0 | E36: =SUM(E15:E35) -> 0 | F36: =SUM(F15:F35) -> 0 | G36: =SUM(G15:G35) -> 0 | H36: =SUM(H15:H35) -> 0 | I36: =SUM(I15:I35) -> 0 | ... P36: =SUM(P15:P35) -> 1 | R36: =SUM(R15:R35) -> 1495 | S36: =SUM(S15:S35) -> 1571 | T36: =+IFERROR(B36/S36-1,"-") -> 0.21133036 | U36: =+IFERROR(B36/R36-1,"-") -> 0.2729097 | W36: =SUM(W15:W35) -> 1495 | X36: =IFERROR(O36/W36-1,"-") -> 0.2729097
A38: Elaboracion/Fuente : AAP - SUNARP

Sheet Marca y mes
A2: Cuadro 03 | U2: ='RESUMEN '!W2 -> Enero
A3: INMATRICULACION DE VEHICULOS PESADOS, SEGÚN MARCA
A4: MARCA | B4: 45658 | C4: 45689 | D4: 45717 | E4: 45748 | F4: 45778 | G4: 45809 | H4: 45839 | I4: 45870 | J4: 45901 | K4: 45931 | L4: 45962 | M4: 45992 | N4: % PART.MES | O4: ='RESUMEN '!O4 -> ACUMULADO 2025 | P4: ='RESUMEN '!P4 -> % Part ACUM 2025 | R4: ='RESUMEN '!R4 -> 45292 | S4: ='RESUMEN '!U4 -> Var. % Ene '25 vs Ene '24 | U4: ='RESUMEN '!W4 -> ACUMULADO 2024 | V4: ='RESUMEN '!X4 -> Var. % ACUM 25/24
A5: VOLVO | B5: 244 | N5: =IFERROR(+B5/$B$58,"-") -> 0.1282186 | O5: =SUM(B5:M5) -> 244 | P5: =+O5/$O$58 -> 0.1282186 | R5: 179 | S5: =+IFERROR(B5/R5-1,"-") -> 0.36312849 | U5: 179 | V5: =IFERROR(O5/U5-1,"-") -> 0.36312849
A6: ISUZU | B6: 210 | N6: =IFERROR(+B6/$B$58,"-") -> 0.11035208 | O6: =SUM(B6:M6) -> 210 | P6: =+O6/$O$58 -> 0.11035208 | R6: 179 | S6: =+IFERROR(B6/R6-1,"-") -> 0.17318436 | U6: 179 | V6: =IFERROR(O6/U6-1,"-") -> 0.17318436
A7: MERCEDES BENZ | B7: 189 | N7: =IFERROR(+B7/$B$58,"-") -> 0.099316868 | O7: =SUM(B7:M7) -> 189 | P7: =+O7/$O$58 -> 0.099316868 | R7: 186 | S7: =+IFERROR(B7/R7-1,"-") -> 0.016129032 | U7: 186 | V7: =IFERROR(O7/U7-1,"-") -> 0.016129032
A8: SCANIA | B8: 157 | N8: =IFERROR(+B8/$B$58,"-") -> 0.082501314 | O8: =SUM(B8:M8) -> 157 | P8: =+O8/$O$58 -> 0.082501314 | R8: 117 | S8: =+IFERROR(B8/R8-1,"-") -> 0.34188034 | U8: 117 | V8: =IFERROR(O8/U8-1,"-") -> 0.34188034
A9: FOTON | B9: 140 | N9: =IFERROR(+B9/$B$58,"-") -> 0.07356805 | O9: =SUM(B9:M9) -> 140 | P9: =+O9/$O$58 -> 0.07356805 | R9: 87 | S9: =+IFERROR(B9/R9-1,"-") -> 0.6091954 | U9: 87 | V9: =IFERROR(O9/U9-1,"-") -> 0.6091954
A10: SINOTRUK | B10: 125 | N10: =IFERROR(+B10/$B$58,"-") -> 0.065685759 | O10: =SUM(B10:M10) -> 125 | P10: =+O10/$O$58 -> 0.065685759 | R10: 68 | S10: =+IFERROR(B10/R10-1,"-") -> 0.83823529 | U10: 68 | V10: =IFERROR(O10/U10-1,"-") -> 0.83823529
A11: HINO | B11: 109 | N11: =IFERROR(+B11/$B$58,"-") -> 0.057277982 | O11: =SUM(B11:M11) -> 109 | P11: =+O11/$O$58 -> 0.057277982 | R11: 111 | S11: =+IFERROR(B11/R11-1,"-") -> -0.018018018 | U11: 111 | V11: =IFERROR(O11/U11-1,"-") -> -0.018018018
A12: FUSO | B12: 107 | N12: =IFERROR(+B12/$B$58,"-") -> 0.05622701 | O12: =SUM(B12:M12) -> 107 | P12: =+O12/$O$58 -> 0.05622701 | R12: 98 | S12: =+IFERROR(B12/R12-1,"-") -> 0.091836735 | U12: 98 | V12: =IFERROR(O12/U12-1,"-") -> 0.091836735
A13: JAC | B13: 94 | N13: =IFERROR(+B13/$B$58,"-") -> 0.049395691 | O13: =SUM(B13:M13) -> 94 | P13: =+O13/$O$58 -> 0.049395691 | R13: 81 | S13: =+IFERROR(B13/R13-1,"-") -> 0.16049383 | U13: 81 | V13: =IFERROR(O13/U13-1,"-") -> 0.16049383
A14: HYUNDAI | B14: 92 | N14: =IFERROR(+B14/$B$58,"-") -> 0.048344719 | O14: =SUM(B14:M14) -> 92 | P14: =+O14/$O$58 -> 0.048344719 | R14: 46 | S14: =+IFERROR(B14/R14-1,"-") -> 1 | U14: 46 | V14: =IFERROR(O14/U14-1,"-") -> 1
A15: SHACMAN | B15: 53 | N15: =IFERROR(+B15/$B$58,"-") -> 0.027850762 | O15: =SUM(B15:M15) -> 53 | P15: =+O15/$O$58 -> 0.027850762 | R15: 79 | S15: =+IFERROR(B15/R15-1,"-") -> -0.32911392 | U15: 79 | V15: =IFERROR(O15/U15-1,"-") -> -0.32911392
A16: FAW | B16: 48 | N16: =IFERROR(+B16/$B$58,"-") -> 0.025223332 | O16: =SUM(B16:M16) -> 48 | P16: =+O16/$O$58 -> 0.025223332 | R16: 15 | S16: =+IFERROR(B16/R16-1,"-") -> 2.2 | U16: 15 | V16: =IFERROR(O16/U16-1,"-") -> 2.2
... A57: SINOTRUK HOMAN | B57: 0 | N57: =IFERROR(+B57/$B$58,"-") -> 0 | O57: =SUM(B57:M57) -> 0 | P57: =+O57/$O$58 -> 0 | R57: 1 | S57: =+IFERROR(B57/R57-1,"-") -> -1 | U57: 1 | V57: =IFERROR(O57/U57-1,"-") -> -1
A58: Total general | B58: =SUM(B5:B57) -> 1903 | C58: =SUM(C5:C57) -> 0 | D58: =SUM(D5:D57) -> 0 | E58: =SUM(E5:E57) -> 0 | F58: =SUM(F5:F57) -> 0 | G58: =SUM(G5:G57) -> 0 | H58: =SUM(H5:H57) -> 0 | I58: =SUM(I5:I57) -> 0 | ... P58: =SUM(P5:P57) -> 1 | R58: =SUM(R5:R57) -> 1495 | S58: =+IFERROR(B58/R58-1,"-") -> 0.2729097 | U58: =SUM(U5:U57) -> 1495 | V58: =IFERROR(O58/U58-1,"-") -> 0.2729097
A60: Elaboracion/Fuente : AAP - SUNARP

Sheet Camion y Tracto
A2: Cuadro 04 | U2: =+'Marca y mes'!U2:V2 -> Enero
A3: INMATRICULACION DE VEHICULOS PESADOS - CLASE DE VEHICULO: "CAMIONES", SEGÚN MARCA
A4: MARCA | B4: 45658 | C4: 45689 | D4: 45717 | E4: 45748 | F4: 45778 | G4: 45809 | H4: 45839 | I4: 45870 | J4: 45901 | K4: 45931 | L4: 45962 | M4: 45992 | N4: % PART.MES | O4: ='Marca y mes'!O4 -> ACUMULADO 2025 | P4: ='RESUMEN '!P4 -> % Part ACUM 2025 | R4: =+'Marca y mes'!R4 -> 45292 | S4: ='RESUMEN '!U4 -> Var. % Ene '25 vs Ene '24 | U4: ='RESUMEN '!W4 -> ACUMULADO 2024 | V4: ='RESUMEN '!X4 -> Var. % ACUM 25/24
A5: ISUZU | B5: 210 | N5: =IFERROR(+B5/$B$42,"-") -> 0.17632242 | O5: =SUM(B5:M5) -> 210 | P5: =+O5/$O$42 -> 0.17632242 | R5: 178 | S5: =+IFERROR(B5/R5-1,"-") -> 0.17977528 | U5: 178 | V5: =IFERROR(O5/U5-1,"-") -> 0.17977528
A6: VOLVO | B6: 149 | N6: =IFERROR(+B6/$B$42,"-") -> 0.12510495 | O6: =SUM(B6:M6) -> 149 | P6: =+O6/$O$42 -> 0.12510495 | R6: 119 | S6: =+IFERROR(B6/R6-1,"-") -> 0.25210084 | U6: 119 | V6: =IFERROR(O6/U6-1,"-") -> 0.25210084
A7: HINO | B7: 106 | N7: =IFERROR(+B7/$B$42,"-") -> 0.08900084 | O7: =SUM(B7:M7) -> 106 | P7: =+O7/$O$42 -> 0.08900084 | R7: 107 | S7: =+IFERROR(B7/R7-1,"-") -> -0.0093457944 | U7: 107 | V7: =IFERROR(O7/U7-1,"-") -> -0.0093457944
A8: SINOTRUK | B8: 101 | N8: =IFERROR(+B8/$B$42,"-") -> 0.084802687 | O8: =SUM(B8:M8) -> 101 | P8: =+O8/$O$42 -> 0.084802687 | R8: 64 | S8: =+IFERROR(B8/R8-1,"-") -> 0.578125 | U8: 64 | V8: =IFERROR(O8/U8-1,"-") -> 0.578125
A9: MERCEDES BENZ | B9: 87 | N9: =IFERROR(+B9/$B$42,"-") -> 0.073047859 | O9: =SUM(B9:M9) -> 87 | P9: =+O9/$O$42 -> 0.073047859 | R9: 124 | S9: =+IFERROR(B9/R9-1,"-") -> -0.2983871 | U9: 124 | V9: =IFERROR(O9/U9-1,"-") -> -0.2983871
A10: FOTON | B10: 84 | N10: =IFERROR(+B10/$B$42,"-") -> 0.070528967 | O10: =SUM(B10:M10) -> 84 | P10: =+O10/$O$42 -> 0.070528967 | R10: 53 | S10: =+IFERROR(B10/R10-1,"-") -> 0.58490566 | U10: 53 | V10: =IFERROR(O10/U10-1,"-") -> 0.58490566
A11: FUSO | B11: 82 | N11: =IFERROR(+B11/$B$42,"-") -> 0.068849706 | O11: =SUM(B11:M11) -> 82 | P11: =+O11/$O$42 -> 0.068849706 | R11: 85 | S11: =+IFERROR(B11/R11-1,"-") -> -0.035294118 | U11: 85 | V11: =IFERROR(O11/U11-1,"-") -> -0.035294118
A12: JAC | B12: 76 | N12: =IFERROR(+B12/$B$42,"-") -> 0.063811923 | O12: =SUM(B12:M12) -> 76 | P12: =+O12/$O$42 -> 0.063811923 | R12: 68 | S12: =+IFERROR(B12/R12-1,"-") -> 0.11764706 | U12: 68 | V12: =IFERROR(O12/U12-1,"-") -> 0.11764706
A13: HYUNDAI | B13: 50 | N13: =IFERROR(+B13/$B$42,"-") -> 0.041981528 | O13: =SUM(B13:M13) -> 50 | P13: =+O13/$O$42 -> 0.041981528 | R13: 29 | S13: =+IFERROR(B13/R13-1,"-") -> 0.72413793 | U13: 29 | V13: =IFERROR(O13/U13-1,"-") -> 0.72413793
A14: SCANIA | B14: 38 | N14: =IFERROR(+B14/$B$42,"-") -> 0.031905961 | O14: =SUM(B14:M14) -> 38 | P14: =+O14/$O$42 -> 0.031905961 | R14: 23 | S14: =+IFERROR(B14/R14-1,"-") -> 0.65217391 | U14: 23 | V14: =IFERROR(O14/U14-1,"-") -> 0.65217391
A15: SHACMAN | B15: 30 | N15: =IFERROR(+B15/$B$42,"-") -> 0.025188917 | O15: =SUM(B15:M15) -> 30 | P15: =+O15/$O$42 -> 0.025188917 | R15: 46 | S15: =+IFERROR(B15/R15-1,"-") -> -0.34782609 | U15: 46 | V15: =IFERROR(O15/U15-1,"-") -> -0.34782609
A16: FAW | B16: 29 | N16: =IFERROR(+B16/$B$42,"-") -> 0.024349286 | O16: =SUM(B16:M16) -> 29 | P16: =+O16/$O$42 -> 0.024349286 | R16: 9 | S16: =+IFERROR(B16/R16-1,"-") -> 2.2222222 | U16: 9 | V16: =IFERROR(O16/U16-1,"-") -> 2.2222222
... A41: SINOTRUK HOMAN | B41: 0 | N41: =IFERROR(+B41/$B$42,"-") -> 0 | O41: =SUM(B41:M41) -> 0 | P41: =+O41/$O$42 -> 0 | R41: 1 | S41: =+IFERROR(B41/R41-1,"-") -> -1 | U41: 1 | V41: =IFERROR(O41/U41-1,"-") -> -1
A42: Total general | B42: =SUM(B5:B41) -> 1191 | C42: =SUM(C5:C41) -> 0 | D42: =SUM(D5:D41) -> 0 | E42: =SUM(E5:E41) -> 0 | F42: =SUM(F5:F41) -> 0 | G42: =SUM(G5:G41) -> 0 | H42: =SUM(H5:H41) -> 0 | I42: =SUM(I5:I41) -> 0 | ... P42: =SUM(P5:P41) -> 1 | R42: =SUM(R5:R41) -> 1050 | S42: =+IFERROR(B42/R42-1,"-") -> 0.13428571 | U42: =SUM(U5:U41) -> 1050 | V42: =IFERROR(O42/U42-1,"-") -> 0.13428571
A44: Elaboracion/Fuente : AAP - SUNARP
A46: Cuadro 05 | U46: =+U2 -> Enero
A47: INMATRICULACION DE VEHICULOS PESADOS - CLASE DE VEHICULO: "TRACTOCAMIONES", SEGÚN MARCA
A48: MARCA | B48: 45292 | C48: 45323 | D48: 45352 | E48: 45383 | F48: 45413 | G48: 45444 | H48: 45474 | I48: 45505 | J48: 45536 | K48: 45566 | L48: 45597 | M48: 45627 | N48: % PART.MES | O48: ='RESUMEN '!O4 -> ACUMULADO 2025 | P48: ='RESUMEN '!P4 -> % Part ACUM 2025 | R48: =+'Marca y mes'!R4 -> 45292 | S48: ='RESUMEN '!U4 -> Var. % Ene '25 vs Ene '24 | U48: ='RESUMEN '!W4 -> ACUMULADO 2024 | V48: ='RESUMEN '!X4 -> Var. % ACUM 25/24
A49: SCANIA | B49: 99 | N49: =IFERROR(+B49/$B$64,"-") -> 0.26612903 | O49: =SUM(B49:M49) -> 99 | P49: =+O49/$O$64 -> 0.26612903 | R49: 93 | S49: =+IFERROR(B49/R49-1,"-") -> 0.064516129 | U49: 93 | V49: =IFERROR(O49/U49-1,"-") -> 0.064516129
A50: VOLVO | B50: 83 | N50: =IFERROR(+B50/$B$64,"-") -> 0.22311828 | O50: =SUM(B50:M50) -> 83 | P50: =+O50/$O$64 -> 0.22311828 | R50: 48 | S50: =+IFERROR(B50/R50-1,"-") -> 0.72916667 | U50: 48 | V50: =IFERROR(O50/U50-1,"-") -> 0.72916667
A51: FOTON | B51: 34 | N51: =IFERROR(+B51/$B$64,"-") -> 0.091397849 | O51: =SUM(B51:M51) -> 34 | P51: =+O51/$O$64 -> 0.091397849 | R51: 20 | S51: =+IFERROR(B51/R51-1,"-") -> 0.7 | U51: 20 | V51: =IFERROR(O51/U51-1,"-") -> 0.7
A52: INTERNATIONAL | B52: 28 | N52: =IFERROR(+B52/$B$64,"-") -> 0.075268817 | O52: =SUM(B52:M52) -> 28 | P52: =+O52/$O$64 -> 0.075268817 | R52: 7 | S52: =+IFERROR(B52/R52-1,"-") -> 3 | U52: 7 | V52: =IFERROR(O52/U52-1,"-") -> 3
A53: SINOTRUK | B53: 24 | N53: =IFERROR(+B53/$B$64,"-") -> 0.064516129 | O53: =SUM(B53:M53) -> 24 | P53: =+O53/$O$64 -> 0.064516129 | R53: 4 | S53: =+IFERROR(B53/R53-1,"-") -> 5 | U53: 4 | V53: =IFERROR(O53/U53-1,"-") -> 5
A54: SHACMAN | B54: 23 | N54: =IFERROR(+B54/$B$64,"-") -> 0.061827957 | O54: =SUM(B54:M54) -> 23 | P54: =+O54/$O$64 -> 0.061827957 | R54: 33 | S54: =+IFERROR(B54/R54-1,"-") -> -0.3030303 | U54: 33 | V54: =IFERROR(O54/U54-1,"-") -> -0.3030303
A55: KENWORTH | B55: 20 | N55: =IFERROR(+B55/$B$64,"-") -> 0.053763441 | O55: =SUM(B55:M55) -> 20 | P55: =+O55/$O$64 -> 0.053763441 | R55: 4 | S55: =+IFERROR(B55/R55-1,"-") -> 4 | U55: 4 | V55: =IFERROR(O55/U55-1,"-") -> 4
A56: FAW | B56: 19 | N56: =IFERROR(+B56/$B$64,"-") -> 0.051075269 | O56: =SUM(B56:M56) -> 19 | P56: =+O56/$O$64 -> 0.051075269 | R56: 6 | S56: =+IFERROR(B56/R56-1,"-") -> 2.1666667 | U56: 6 | V56: =IFERROR(O56/U56-1,"-") -> 2.1666667
A57: MERCEDES BENZ | B57: 18 | N57: =IFERROR(+B57/$B$64,"-") -> 0.048387097 | O57: =SUM(B57:M57) -> 18 | P57: =+O57/$O$64 -> 0.048387097 | R57: 5 | S57: =+IFERROR(B57/R57-1,"-") -> 2.6 | U57: 5 | V57: =IFERROR(O57/U57-1,"-") -> 2.6
A58: FREIGHTLINER | B58: 10 | N58: =IFERROR(+B58/$B$64,"-") -> 0.02688172 | O58: =SUM(B58:M58) -> 10 | P58: =+O58/$O$64 -> 0.02688172 | R58: 12 | S58: =+IFERROR(B58/R58-1,"-") -> -0.16666667 | U58: 12 | V58: =IFERROR(O58/U58-1,"-") -> -0.16666667
A59: SITRAK | B59: 6 | N59: =IFERROR(+B59/$B$64,"-") -> 0.016129032 | O59: =SUM(B59:M59) -> 6 | P59: =+O59/$O$64 -> 0.016129032 | R59: 6 | S59: =+IFERROR(B59/R59-1,"-") -> 0 | U59: 6 | V59: =IFERROR(O59/U59-1,"-") -> 0
A60: HOWO MAX | B60: 5 | N60: =IFERROR(+B60/$B$64,"-") -> 0.01344086 | O60: =SUM(B60:M60) -> 5 | P60: =+O60/$O$64 -> 0.01344086 | R60: 0 | S60: =+IFERROR(B60/R60-1,"-") -> - | U60: 0 | V60: =IFERROR(O60/U60-1,"-") -> -
... A63: CAMC | B63: 0 | N63: =IFERROR(+B63/$B$64,"-") -> 0 | O63: =SUM(B63:M63) -> 0 | P63: =+O63/$O$64 -> 0 | R63: 2 | S63: =+IFERROR(B63/R63-1,"-") -> -1 | U63: 2 | V63: =IFERROR(O63/U63-1,"-") -> -1
A64: Total general | B64: =SUM(B49:B63) -> 372 | C64: =SUM(C49:C63) -> 0 | D64: =SUM(D49:D63) -> 0 | E64: =SUM(E49:E63) -> 0 | F64: =SUM(F49:F63) -> 0 | G64: =SUM(G49:G63) -> 0 | H64: =SUM(H49:H63) -> 0 | I64: =SUM(I49:I63) -> 0 | ... P64: =SUM(P49:P63) -> 1 | R64: =SUM(R49:R63) -> 254 | S64: =+IFERROR(B64/R64-1,"-") -> 0.46456693 | U64: =SUM(U49:U63) -> 254 | V64: =IFERROR(O64/U64-1,"-") -> 0.46456693
A66: Elaboracion/Fuente : AAP - SUNARP

Sheet Minibus,Omnibus
A2: Duadro 06 | U2: ='RESUMEN '!W2 -> Enero
A3: INMATRICULACION DE VEHICULOS PESADOS - CLASE DE VEHICULO: "MINIBUS,OMNIBUS", SEGÚN MARCA
A4: MARCA | B4: 45658 | C4: 45689 | D4: 45717 | E4: 45748 | F4: 45778 | G4: 45809 | H4: 45839 | I4: 45870 | J4: 45901 | K4: 45931 | L4: 45962 | M4: 45992 | N4: % PART.MES | O4: ='RESUMEN '!O4 -> ACUMULADO 2025 | P4: ='RESUMEN '!P4 -> % Part ACUM 2025 | R4: =+'Camion y Tracto'!R48 -> 45292 | S4: ='RESUMEN '!U4 -> Var. % Ene '25 vs Ene '24 | U4: ='RESUMEN '!W4 -> ACUMULADO 2024 | V4: ='RESUMEN '!X4 -> Var. % ACUM 25/24
A5: MERCEDES BENZ | B5: 84 | N5: =IFERROR(+B5/$B$31,"-") -> 0.24705882 | O5: =SUM(B5:M5) -> 84 | P5: =+O5/$O$31 -> 0.24705882 | R5: 57 | S5: =+IFERROR(B5/R5-1,"-") -> 0.47368421 | U5: 57 | V5: =IFERROR(O5/U5-1,"-") -> 0.47368421
A6: HYUNDAI | B6: 42 | N6: =IFERROR(+B6/$B$31,"-") -> 0.12352941 | O6: =SUM(B6:M6) -> 42 | P6: =+O6/$O$31 -> 0.12352941 | R6: 17 | S6: =+IFERROR(B6/R6-1,"-") -> 1.4705882 | U6: 17 | V6: =IFERROR(O6/U6-1,"-") -> 1.4705882
A7: FUSO | B7: 25 | N7: =IFERROR(+B7/$B$31,"-") -> 0.073529412 | O7: =SUM(B7:M7) -> 25 | P7: =+O7/$O$31 -> 0.073529412 | R7: 13 | S7: =+IFERROR(B7/R7-1,"-") -> 0.92307692 | U7: 13 | V7: =IFERROR(O7/U7-1,"-") -> 0.92307692
A8: JOYLONG | B8: 23 | N8: =IFERROR(+B8/$B$31,"-") -> 0.067647059 | O8: =SUM(B8:M8) -> 23 | P8: =+O8/$O$31 -> 0.067647059 | R8: 5 | S8: =+IFERROR(B8/R8-1,"-") -> 3.6 | U8: 5 | V8: =IFERROR(O8/U8-1,"-") -> 3.6
A9: FOTON | B9: 22 | N9: =IFERROR(+B9/$B$31,"-") -> 0.064705882 | O9: =SUM(B9:M9) -> 22 | P9: =+O9/$O$31 -> 0.064705882 | R9: 14 | S9: =+IFERROR(B9/R9-1,"-") -> 0.57142857 | U9: 14 | V9: =IFERROR(O9/U9-1,"-") -> 0.57142857
A10: SCANIA | B10: 20 | N10: =IFERROR(+B10/$B$31,"-") -> 0.058823529 | O10: =SUM(B10:M10) -> 20 | P10: =+O10/$O$31 -> 0.058823529 | R10: 1 | S10: =+IFERROR(B10/R10-1,"-") -> 19 | U10: 1 | V10: =IFERROR(O10/U10-1,"-") -> 19
A11: VOLKSWAGEN | B11: 19 | N11: =IFERROR(+B11/$B$31,"-") -> 0.055882353 | O11: =SUM(B11:M11) -> 19 | P11: =+O11/$O$31 -> 0.055882353 | R11: 7 | S11: =+IFERROR(B11/R11-1,"-") -> 1.7142857 | U11: 7 | V11: =IFERROR(O11/U11-1,"-") -> 1.7142857
A12: YUTONG | B12: 18 | N12: =IFERROR(+B12/$B$31,"-") -> 0.052941176 | O12: =SUM(B12:M12) -> 18 | P12: =+O12/$O$31 -> 0.052941176 | R12: 3 | S12: =+IFERROR(B12/R12-1,"-") -> 5 | U12: 3 | V12: =IFERROR(O12/U12-1,"-") -> 5
A13: JAC | B13: 18 | N13: =IFERROR(+B13/$B$31,"-") -> 0.052941176 | O13: =SUM(B13:M13) -> 18 | P13: =+O13/$O$31 -> 0.052941176 | R13: 13 | S13: =+IFERROR(B13/R13-1,"-") -> 0.38461538 | U13: 13 | V13: =IFERROR(O13/U13-1,"-") -> 0.38461538
A14: KING LONG | B14: 16 | N14: =IFERROR(+B14/$B$31,"-") -> 0.047058824 | O14: =SUM(B14:M14) -> 16 | P14: =+O14/$O$31 -> 0.047058824 | R14: 2 | S14: =+IFERROR(B14/R14-1,"-") -> 7 | U14: 2 | V14: =IFERROR(O14/U14-1,"-") -> 7
A15: IVECO | B15: 15 | N15: =IFERROR(+B15/$B$31,"-") -> 0.044117647 | O15: =SUM(B15:M15) -> 15 | P15: =+O15/$O$31 -> 0.044117647 | R15: 16 | S15: =+IFERROR(B15/R15-1,"-") -> -0.0625 | U15: 16 | V15: =IFERROR(O15/U15-1,"-") -> -0.0625
A16: VOLVO | B16: 12 | N16: =IFERROR(+B16/$B$31,"-") -> 0.035294118 | O16: =SUM(B16:M16) -> 12 | P16: =+O16/$O$31 -> 0.035294118 | R16: 12 | S16: =+IFERROR(B16/R16-1,"-") -> 0 | U16: 12 | V16: =IFERROR(O16/U16-1,"-") -> 0
... A30: HIGER | B30: 0 | N30: =IFERROR(+B30/$B$31,"-") -> 0 | O30: =SUM(B30:M30) -> 0 | P30: =+O30/$O$31 -> 0 | R30: 1 | S30: =+IFERROR(B30/R30-1,"-") -> -1 | U30: 1 | V30: =IFERROR(O30/U30-1,"-") -> -1
A31: Total general | B31: =SUM(B5:B30) -> 340 | C31: =SUM(C5:C30) -> 0 | D31: =SUM(D5:D30) -> 0 | E31: =SUM(E5:E30) -> 0 | F31: =SUM(F5:F30) -> 0 | G31: =SUM(G5:G30) -> 0 | H31: =SUM(H5:H30) -> 0 | I31: =SUM(I5:I30) -> 0 | ... P31: =SUM(P5:P30) -> 1 | R31: =SUM(R5:R30) -> 191 | S31: =+IFERROR(B31/R31-1,"-") -> 0.78010471 | U31: =SUM(U5:U30) -> 191 | V31: =IFERROR(O31/U31-1,"-") -> 0.78010471
A33: Elaboracion/Fuente : AAP - SUNARP

Sheet Camion Marca y Modelo
A2: Cuadro 08
A3: Registro de Placas de Vehículos "Camiones" nuevos por Marca y Modelo
A4: MARCA | B4: MODELO | C4: Ene | D4: Feb | E4: Mar | F4: Abr | G4: May | H4: Jun | I4: Jul | J4: Ago | K4: Sep | L4: Oct | M4: Nov | N4: Dic | O4: Total
A5: DONGFENG | B5: DF-1718 | C5: 1 | O5: =SUM(C5:N5) -> 1
B6: EQ1160GD5NJ | C6: 20 | O6: =SUM(C6:N6) -> 20
B7: DF-814 | C7: 1 | O7: =SUM(C7:N7) -> 1
B8: DFH5180 | C8: 1 | O8: =SUM(C8:N8) -> 1
B9: DFH1140B | C9: 2 | O9: =SUM(C9:N9) -> 2
A10: FAW | B10: CA3250P25K15L3T1E5A80 | C10: 19 | O10: =SUM(C10:N10) -> 19
B11: CA1121P40K2L5E5A85 | C11: 5 | O11: =SUM(C11:N11) -> 5
B12: CA5250P25K15L3T1E5A80 | C12: 2 | O12: =SUM(C12:N12) -> 2
B13: CA1070P40K50L1E5A84 | C13: 2 | O13: =SUM(C13:N13) -> 2
B14: CA1120P28K38L4E5A80 | C14: 1 | O14: =SUM(C14:N14) -> 1
A15: FORD | B15: F-350 | C15: 1 | O15: =SUM(C15:N15) -> 1
B16: F-450 | C16: 1 | O16: =SUM(C16:N16) -> 1
A17: FORLAND | B17: FD250 | C17: 2 | O17: =SUM(C17:N17) -> 2
B18: FD800 | C18: 2 | O18: =SUM(C18:N18) -> 2
B19: F300NL | C19: 1 | O19: =SUM(C19:N19) -> 1
B20: F1100 CH | C20: 1 | O20: =SUM(C20:N20) -> 1
B21: F500S VIP CHC | C21: 1 | O21: =SUM(C21:N21) -> 1
B22: F1300L CH | C22: 1 | O22: =SUM(C22:N22) -> 1
B23: F400 VIP CB | C23: 2 | O23: =SUM(C23:N23) -> 2
B24: F400 VIP | C24: 3 | O24: =SUM(C24:N24) -> 3
B25: F400VIP DC | C25: 5 | O25: =SUM(C25:N25) -> 5
B26: FD800N | C26: 4 | O26: =SUM(C26:N26) -> 4
A27: FOTON | B27: AUMARK E 3T BAR | C27: 4 | O27: =SUM(C27:N27) -> 4
B28: AUMARK E 4T BAR | C28: 4 | O28: =SUM(C28:N28) -> 4
B29: AUMARK E 4T CH | C29: 9 | O29: =SUM(C29:N29) -> 9
B30: BJ1041V8ADA-F1 | C30: 1 | O30: =SUM(C30:N30) -> 1
B31: BJ1065VDJD4-F1 | C31: 3 | O31: =SUM(C31:N31) -> 3
B32: BJ1065VDJDA-F1 | C32: 12 | O32: =SUM(C32:N32) -> 12
B33: BJ1088VFJEA-F1 | C33: 3 | O33: =SUM(C33:N33) -> 3
B34: BJ1108VEJED-FA | C34: 6 | O34: =SUM(C34:N34) -> 6
B35: BJ1126VGPFG-F2 | C35: 3 | O35: =SUM(C35:N35) -> 3
B36: BJ1186VLPHK-AA | C36: 1 | O36: =SUM(C36:N36) -> 1
B37: BJ1226VMPHN-AA | C37: 3 | O37: =SUM(C37:N37) -> 3
B38: BJ1356VRPHP-AA | C38: 3 | O38: =SUM(C38:N38) -> 3
B39: BJ3259DLPKB-A1 | C39: 7 | O39: =SUM(C39:N39) -> 7
... B50: BJ5311GJB-MD | C50: 1 | O50: =SUM(C50:N50) -> 1
A51: FUSO | B51: CANTER | C51: 69 | O51: =SUM(C51:N51) -> 69
...

Sheet Tracto Marca y Modelo
A2: Cuadro 09
A3: Registro de Placas nuevas de Vehículos "Tracto" nuevos por Marca y Modelo
A4: MARCA | B4: MODELO | C4: Ene | D4: Feb | E4: Mar | F4: Abr | G4: May | H4: Jun | I4: Jul | J4: Ago | K4: Sep | L4: Oct | M4: Nov | N4: Dic | O4: Total
A5: DONGFENG | B5: DFH4271 | C5: 3 | O5: =SUM(C5:N5) -> 3
A6: FAW | B6: CA4250P25K15T1NE5A80 | C6: 4 | O6: =SUM(C6:N6) -> 4
B7: CA4250P26K15T1E5A80 | C7: 1 | O7: =SUM(C7:N7) -> 1
B8: CA4250P25K2T1E5A80 | C8: 1 | O8: =SUM(C8:N8) -> 1
B9: CA4250P77K25T1E5 | C9: 1 | O9: =SUM(C9:N9) -> 1
B10: CA4252P25K15T1NE6A80 | C10: 11 | O10: =SUM(C10:N10) -> 11
B11: CA4254P25K15T1NE6A80 | C11: 1 | O11: =SUM(C11:N11) -> 1
A12: FOTON | B12: BJ4189SLFKA-A4 | C12: 4 | O12: =SUM(C12:N12) -> 4
B13: BJ4259SMFKB-AB | C13: 4 | O13: =SUM(C13:N13) -> 4
B14: BJ4269SNFKB-A4 | C14: 25 | O14: =SUM(C14:N14) -> 25
B15: BJ4269SNFKB-1A | C15: 1 | O15: =SUM(C15:N15) -> 1
A16: FREIGHTLINER | B16: 114SD | C16: 2 | O16: =SUM(C16:N16) -> 2
B17: NEW CASCADIA | C17: 8 | O17: =SUM(C17:N17) -> 8
A18: INTERNATIONAL | B18: HV613 SBA 6X4 | C18: 1 | O18: =SUM(C18:N18) -> 1
B19: LT625 6X4 | C19: 25 | O19: =SUM(C19:N19) -> 25
B20: HV607 SBA HD 6X4 | C20: 2 | O20: =SUM(C20:N20) -> 2
A21: KENWORTH | B21: T880 | C21: 20 | O21: =SUM(C21:N21) -> 20
A22: MERCEDES BENZ | B22: NEW ACTROS 2645LS | C22: 16 | O22: =SUM(C22:N22) -> 16
B23: NEW ACTROS 2648LS | C23: 2 | O23: =SUM(C23:N23) -> 2
A24: SCANIA | B24: G410 A6X4 | C24: 3 | O24: =SUM(C24:N24) -> 3
B25: P450 A4X2 | C25: 1 | O25: =SUM(C25:N25) -> 1
B26: P450 A6X4 | C26: 24 | O26: =SUM(C26:N26) -> 24
B27: R500 A6X4 | C27: 40 | O27: =SUM(C27:N27) -> 40
B28: R540 A6X4 | C28: 13 | O28: =SUM(C28:N28) -> 13
B29: R450 A6X4 | C29: 13 | O29: =SUM(C29:N29) -> 13
B30: R550 A6X4 | C30: 3 | O30: =SUM(C30:N30) -> 3
B31: S550 A6X4 | C31: 2 | O31: =SUM(C31:N31) -> 2
A32: SHACMAN | B32: SX42584Y344C | C32: 4 | O32: =SUM(C32:N32) -> 4
B33: SX4258GV404T | C33: 6 | O33: =SUM(C33:N33) -> 6
B34: SX42585Y344C | C34: 6 | O34: =SUM(C34:N34) -> 6
B35: SX4258Y4344C | C35: 4 | O35: =SUM(C35:N35) -> 4
B36: SX4255H3K49B3640 | C36: 2 | O36: =SUM(C36:N36) -> 2
B37: SX42595X384TL | C37: 1 | O37: =SUM(C37:N37) -> 1
A38: SINOTRUK | B38: ZZ4257V344HE1 | C38: 10 | O38: =SUM(C38:N38) -> 10
B39: ZZ4257V384HE1C | C39: 5 | O39: =SUM(C39:N39) -> 5
B40: ZZ4257V424KE1CK | C40: 6 | O40: =SUM(C40:N40) -> 6
B41: ZZ4257V344HB1 | C41: 1 | O41: =SUM(C41:N41) -> 1
...

Sheet Minibus,Omnibus Marca y Mod
A2: Cuadro 10
A3: Registro de Placas de Vehículos "Minibus,Omnibus" nuevos por marca y modelo (Mayor a 17 Pasajeros)
A4: MARCA | B4: MODELO | C4: Ene | D4: Feb | E4: Mar | F4: Abr | G4: May | H4: Jun | I4: Jul | J4: Ago | K4: Sep | L4: Oct | M4: Nov | N4: Dic | O4: Total
A5: EURISE | B5: YBL6750D | C5: 6 | O5: =SUM(C5:N5) -> 6
A6: FOTON | B6: BJ6608B1DDA-AB | C6: 2 | O6: =SUM(C6:N6) -> 2
B7: BJ6670BF01A | C7: 1 | O7: =SUM(C7:N7) -> 1
B8: BJ6730 | C8: 2 | O8: =SUM(C8:N8) -> 2
B9: K0 E4 | C9: 15 | O9: =SUM(C9:N9) -> 15
B10: TOANO | C10: 2 | O10: =SUM(C10:N10) -> 2
A11: FUSO | B11: MF 100 | C11: 2 | O11: =SUM(C11:N11) -> 2
B12: ROSA | C12: 22 | O12: =SUM(C12:N12) -> 22
B13: MF100 | C13: 1 | O13: =SUM(C13:N13) -> 1
A14: HINO | B14: FC BUS | C14: 3 | O14: =SUM(C14:N14) -> 3
A15: HYUNDAI | B15: COUNTY | C15: 28 | O15: =SUM(C15:N15) -> 28
B16: H350 | C16: 5 | O16: =SUM(C16:N16) -> 5
B17: COUNTY BX | C17: 1 | O17: =SUM(C17:N17) -> 1
B18: BX8 | C18: 6 | O18: =SUM(C18:N18) -> 6
B19: BX11 | C19: 2 | O19: =SUM(C19:N19) -> 2
A20: IVECO | B20: 170S28 | C20: 1 | O20: =SUM(C20:N20) -> 1
B21: DAILY MINIBUS | C21: 6 | O21: =SUM(C21:N21) -> 6
B22: 10.190 | C22: 1 | O22: =SUM(C22:N22) -> 1
B23: 150S21 | C23: 7 | O23: =SUM(C23:N23) -> 7
A24: JAC | B24: SUNRAY | C24: 18 | O24: =SUM(C24:N24) -> 18
A25: JMC | B25: N520 | C25: 1 | O25: =SUM(C25:N25) -> 1
A26: JOYLONG | B26: HKL6480C | C26: 1 | O26: =SUM(C26:N26) -> 1
B27: HKL6540C | C27: 1 | O27: =SUM(C27:N27) -> 1
B28: HKL6600C | C28: 21 | O28: =SUM(C28:N28) -> 21
A29: KING LONG | B29: KINGO 20 | C29: 6 | O29: =SUM(C29:N29) -> 6
B30: KINGO D17 | C30: 3 | O30: =SUM(C30:N30) -> 3
B31: XMQ6130E | C31: 3 | O31: =SUM(C31:N31) -> 3
B32: XMQ6127G | C32: 2 | O32: =SUM(C32:N32) -> 2
B33: XMQ6900E | C33: 2 | O33: =SUM(C33:N33) -> 2
A34: MAXUS | B34: V90 | C34: 5 | O34: =SUM(C34:N34) -> 5
B35: EV90 | C35: 1 | O35: =SUM(C35:N35) -> 1
A36: MERCEDES BENZ | B36: LO 916 | C36: 9 | O36: =SUM(C36:N36) -> 9
B37: O-500 RS | C37: 6 | O37: =SUM(C37:N37) -> 6
B38: O-500 RSD | C38: 33 | O38: =SUM(C38:N38) -> 33
B39: OF 1724 | C39: 1 | O39: =SUM(C39:N39) -> 1
B40: OF 1730 | C40: 2 | O40: =SUM(C40:N40) -> 2
B41: OF-1724 | C41: 2 | O41: =SUM(C41:N41) -> 2
...

Sheet Zon.Reg I al XIII
A2: Cuadro 11
A3: Registro de Placas de Vehículos "Pesados" nuevos por Zona Registral I al XIII
A4: ZONA REGISTRAL | B4: MARCA | C4: MODELO | D4: Ene | E4: Feb | F4: Mar | G4: Abr | H4: May | I4: Jun | J4: Jul | K4: Ago | L4: Sep | M4: Oct | N4: Nov | O4: Dic | P4: Total
A5: ZONA REGISTRAL N° I | B5: FUSO | C5: ROSA | D5: 1 | P5: =SUM(D5:O5) -> 1
B6: HINO | C6: DUTRO | D6: 2 | P6: =SUM(D6:O6) -> 2
B7: HYUNDAI | C7: EX10 | D7: 1 | P7: =SUM(D7:O7) -> 1
B8: ISUZU | C8: NQR90L-MQ5VAYPEN | D8: 3 | P8: =SUM(D8:O8) -> 3
B9: JAC | C9: HFC1040KN | D9: 5 | P9: =SUM(D9:O9) -> 5
C10: SUNRAY | D10: 4 | P10: =SUM(D10:O10) -> 4
C11: HFC1040KRN-2 | D11: 1 | P11: =SUM(D11:O11) -> 1
B12: JMC | C12: CARRYING PLUS | D12: 1 | P12: =SUM(D12:O12) -> 1
A13: ZONA REGISTRAL N° II | B13: FORLAND | C13: F400 VIP | D13: 1 | P13: =SUM(D13:O13) -> 1
C14: F400VIP DC | D14: 1 | P14: =SUM(D14:O14) -> 1
B15: FOTON | C15: AUMARK E 3T BAR | D15: 1 | P15: =SUM(D15:O15) -> 1
B16: FUSO | C16: CANTER | D16: 7 | P16: =SUM(D16:O16) -> 7
B17: HINO | C17: DUTRO | D17: 4 | P17: =SUM(D17:O17) -> 4
C18: GD | D18: 1 | P18: =SUM(D18:O18) -> 1
C19: FC | D19: 1 | P19: =SUM(D19:O19) -> 1
C20: FM | D20: 1 | P20: =SUM(D20:O20) -> 1
C21: GH | D21: 1 | P21: =SUM(D21:O21) -> 1
C22: FD | D22: 1 | P22: =SUM(D22:O22) -> 1
B23: HYUNDAI | C23: H350 | D23: 2 | P23: =SUM(D23:O23) -> 2
C24: EX6 | D24: 1 | P24: =SUM(D24:O24) -> 1
C25: EX8 | D25: 1 | P25: =SUM(D25:O25) -> 1
B26: ISUZU | C26: FRR | D26: 1 | P26: =SUM(D26:O26) -> 1
C27: FVR34UL-QDPES | D27: 3 | P27: =SUM(D27:O27) -> 3
C28: NLR85L-EE1AYPE | D28: 3 | P28: =SUM(D28:O28) -> 3
C29: NPR75L-HL5VAYPEN | D29: 2 | P29: =SUM(D29:O29) -> 2
C30: NPR75L-KL5VAYPEN | D30: 2 | P30: =SUM(D30:O30) -> 2
C31: NPS75L-HJ5VAYPEN | D31: 1 | P31: =SUM(D31:O31) -> 1
B32: IVECO ASTRA | C32: HD9 64.48 | D32: 2 | P32: =SUM(D32:O32) -> 2
B33: JAC | C33: HFC1040KN | D33: 2 | P33: =SUM(D33:O33) -> 2
B34: JMC | C34: CARRYING PLUS | D34: 2 | P34: =SUM(D34:O34) -> 2
B35: KAMA | C35: KMC1067D4 | D35: 1 | P35: =SUM(D35:O35) -> 1
B36: MERCEDES BENZ | C36: AXOR 3131 | D36: 1 | P36: =SUM(D36:O36) -> 1
C37: AROCS 3345K | D37: 1 | P37: =SUM(D37:O37) -> 1
B38: SINOTRUK | C38: ZZ3048C2813D145 | D38: 1 | P38: =SUM(D38:O38) -> 1
B39: VOLKSWAGEN | C39: 26.280 LR MAN E5 | D39: 1 | P39: =SUM(D39:O39) -> 1
B40: WISU | C40: SCH6430 | D40: 1 | P40: =SUM(D40:O40) -> 1
A41: ZONA REGISTRAL N° III | B41: FUSO | C41: CANTER | D41: 1 | P41: =SUM(D41:O41) -> 1
...

Sheet Oficina y Clase
A2: Cuadro 12
A3: Registro de Placas de Vehículos "Pesados" nuevos por Clase y Oficina
A4: OFICINA | B4: CLASE | C4: MARCA | D4: MODELO | E4: Ene | F4: Feb | G4: Mar | H4: Abr | I4: May | J4: Jun | K4: Jul | L4: Ago | M4: Sep | N4: Oct | O4: Nov | P4: Dic | Q4: Total
A5: AREQUIPA | B5: CAMIONES Y TRACTO | C5: FORLAND | D5: FD250 | E5: 1 | Q5: =SUM(E5:P5) -> 1
D6: F500S VIP CHC | E6: 1 | Q6: =SUM(E6:P6) -> 1
D7: F400VIP DC | E7: 1 | Q7: =SUM(E7:P7) -> 1
D8: FD800N | E8: 2 | Q8: =SUM(E8:P8) -> 2
C9: FOTON | D9: BJ1065VDJDA-F1 | E9: 1 | Q9: =SUM(E9:P9) -> 1
D10: BJ1226VMPHN-AA | E10: 2 | Q10: =SUM(E10:P10) -> 2
D11: BJ4269SNFKB-A4 | E11: 3 | Q11: =SUM(E11:P11) -> 3
D12: BJ1356VRPHP-AA | E12: 1 | Q12: =SUM(E12:P12) -> 1
D13: BJ4259SMFKB-AB | E13: 1 | Q13: =SUM(E13:P13) -> 1
D14: AUMARK E 3T BAR | E14: 3 | Q14: =SUM(E14:P14) -> 3
D15: AUMARK E 4T CH | E15: 1 | Q15: =SUM(E15:P15) -> 1
D16: BJ1099VEJED-FA | E16: 2 | Q16: =SUM(E16:P16) -> 2
D17: 4M3 CUMMINS | E17: 1 | Q17: =SUM(E17:P17) -> 1
D18: BJ4269SNFKB-1A | E18: 1 | Q18: =SUM(E18:P18) -> 1
C19: FREIGHTLINER | D19: NEW CASCADIA | E19: 1 | Q19: =SUM(E19:P19) -> 1
C20: FUSO | D20: CANTER | E20: 13 | Q20: =SUM(E20:P20) -> 13
D21: FI | E21: 1 | Q21: =SUM(E21:P21) -> 1
C22: HINO | D22: DUTRO | E22: 6 | Q22: =SUM(E22:P22) -> 6
D23: GD | E23: 1 | Q23: =SUM(E23:P23) -> 1
D24: FC | E24: 1 | Q24: =SUM(E24:P24) -> 1
D25: FD | E25: 1 | Q25: =SUM(E25:P25) -> 1
C26: HYUNDAI | D26: EX10 | E26: 1 | Q26: =SUM(E26:P26) -> 1
D27: EX6 | E27: 2 | Q27: =SUM(E27:P27) -> 2
D28: EX8 | E28: 5 | Q28: =SUM(E28:P28) -> 5
D29: EX11 | E29: 1 | Q29: =SUM(E29:P29) -> 1
C30: INTERNATIONAL | D30: LT625 6X4 | E30: 7 | Q30: =SUM(E30:P30) -> 7
C31: ISUZU | D31: FRR | E31: 3 | Q31: =SUM(E31:P31) -> 3
D32: FTR34UL-PDPEN | E32: 1 | Q32: =SUM(E32:P32) -> 1
D33: FVR34UL-QDPES | E33: 1 | Q33: =SUM(E33:P33) -> 1
D34: NPR75L-HL5VAYPEN | E34: 4 | Q34: =SUM(E34:P34) -> 4
D35: NPR75L-KL5VAYPEN | E35: 8 | Q35: =SUM(E35:P35) -> 8
D36: NPS75L-HJ5VAYPEN | E36: 7 | Q36: =SUM(E36:P36) -> 7
C37: JAC | D37: HFC1040KN | E37: 1 | Q37: =SUM(E37:P37) -> 1
D38: HFC1055KN | E38: 3 | Q38: =SUM(E38:P38) -> 3
D39: HFC1061KN | E39: 1 | Q39: =SUM(E39:P39) -> 1
D40: HFC1071KN | E40: 2 | Q40: =SUM(E40:P40) -> 2
D41: HFC1083KN | E41: 1 | Q41: =SUM(E41:P41) -> 1
...

Sheet BASE ESPECIFICACIONES TÉCNICAS
A1: Oficina Registral | B1: USO VEHICULO | C1: CLASE AAP | D1: SUB-CLASE | E1: CARROCERIA | F1: CARROCERIA_INM | G1: CATEGORIA | H1: MARCA | I1: MODELO | J1: VERSION | K1: ORIGEN | L1: COMBUSTIBLE | M1: FORMULA RODANTE | N1: PBV | O1: CILINDRADA | P1: # ASIENTO | Q1: AÑO_MOD | R1: ENE
A2: AREQUIPA | B2: Placa Gubernamental - Vehiculos Livianos y Pesados | C2: CAMIONES Y TRACTO | D2: CAMIONES | E2: CHASIS CABINADO | F2: VOLQUETE | G2: N3 | H2: MERCEDES BENZ | I2: AROCS 3345K | J2: AROCS 3345K | K2: GERMANY | L2: DIESEL | M2: 6X4 | N2: 41000 | O2: 12809 | P2: 2 | Q2: 2024 | R2: 2
A3: AREQUIPA | B3: Placa Gubernamental - Vehiculos Livianos y Pesados | C3: MINIBUS,OMNIBUS | D3: BUSES Y CHASISES | E3: MINIBUS | F3: MINIBUS | G3: M3C3 | H3: FUSO | I3: ROSA | J3: EURO 4 | K3: JAPAN | L3: DIESEL | M3: 4X2 | N3: 6200 | O3: 4899 | P3: 33 | Q3: 2025 | R3: 1
A4: AREQUIPA | B4: Vehiculos Motorizados para el Transportes de mercancias (Categoria N) | C4: CAMIONES Y TRACTO | D4: CAMIONES | E4: BARANDA | F4: BARANDA | G4: N2 | H4: FORLAND | I4: F400VIP DC | J4: BJ1046V9JDA-53 | K4: CHINA | L4: DIESEL | M4: 4X2 | N4: 6500 | O4: 2499 | P4: 5 | Q4: 2025 | R4: 1
A5: AREQUIPA | B5: Vehiculos Motorizados para el Transportes de mercancias (Categoria N) | C5: CAMIONES Y TRACTO | D5: CAMIONES | E5: BARANDA | F5: BARANDA | G5: N2 | H5: FOTON | I5: BJ1065VDJDA-F1 | J5: BJ1065VDJDA-F1 | K5: CHINA | L5: DIESEL | M5: 4X2 | N5: 6500 | O5: 2780 | P5: 3 | Q5: 2025 | R5: 1
A6: AREQUIPA | B6: Vehiculos Motorizados para el Transportes de mercancias (Categoria N) | C6: CAMIONES Y TRACTO | D6: CAMIONES | E6: BARANDA | F6: BARANDA | G6: N2 | H6: FOTON | I6: AUMARK E 3T BAR | J6: BJ1065VDJD4-F1 | K6: CHINA | L6: DIESEL | M6: 4X2 | N6: 5900 | O6: 2771 | P6: 3 | Q6: 2024 | R6: 3
A7: AREQUIPA | B7: Vehiculos Motorizados para el Transportes de mercancias (Categoria N) | C7: CAMIONES Y TRACTO | D7: CAMIONES | E7: BARANDA | F7: BARANDA | G7: N2 | H7: JAC | I7: HFC1055KN | J7: SD400 VIP BAR 5.0T EIV 154 HP | K7: CHINA | L7: DIESEL | M7: 4X2 | N7: 8765 | O7: 3800 | P7: 3 | Q7: 2025 | R7: 2
A8: AREQUIPA | B8: Vehiculos Motorizados para el Transportes de mercancias (Categoria N) | C8: CAMIONES Y TRACTO | D8: CAMIONES | E8: BARANDA | F8: BARANDA | G8: N2 | H8: JAC | I8: HFC1061KN | J8: SD500 VIP BAR 6.0T EIV | K8: CHINA | L8: DIESEL | M8: 4X2 | N8: 9280 | O8: 3760 | P8: 3 | Q8: 2025 | R8: 1
A9: AREQUIPA | B9: Vehiculos Motorizados para el Transportes de mercancias (Categoria N) | C9: CAMIONES Y TRACTO | D9: CAMIONES | E9: BARANDA | F9: BARANDA | G9: N2 | H9: JAC | I9: HFC1071KN | J9: D700L VIP BAR 7.0T EIV | K9: CHINA | L9: DIESEL | M9: 4X2 | N9: 10660 | O9: 3760 | P9: 3 | Q9: 2025 | R9: 1
A10: AREQUIPA | B10: Vehiculos Motorizados para el Transportes de mercancias (Categoria N) | C10: CAMIONES Y TRACTO | D10: CAMIONES | E10: BARANDA | F10: BARANDA | G10: N2 | H10: JAC | I10: HFC1040KRN-2 | J10: D400DC VIP 120 HP BAR 4.0T DOB CAB | K10: CHINA | L10: DIESEL | M10: 4X2 | N10: 6560 | O10: 2746 | P10: 6 | Q10: 2025 | R10: 3
A11: AREQUIPA | B11: Vehiculos Motorizados para el Transportes de mercancias (Categoria N) | C11: CAMIONES Y TRACTO | D11: CAMIONES | E11: BARANDA | F11: BARANDA | G11: N2 | H11: JMC | I11: CARRYING PLUS | J11: 4.0T SC DR | K11: CHINA | L11: DIESEL | M11: 4X2 | N11: 6361 | O11: 2771 | P11: 3 | Q11: 2025 | R11: 2
A12: AREQUIPA | B12: Vehiculos Motorizados para el Transportes de mercancias (Categoria N) | C12: CAMIONES Y TRACTO | D12: CAMIONES | E12: BARANDA | F12: BARANDA | G12: N2 | H12: JMC | I12: CARRYING PLUS | J12: 4.0T DC | K12: CHINA | L12: DIESEL | M12: 4X2 | N12: 6361 | O12: 2771 | P12: 6 | Q12: 2025 | R12: 1
A13: AREQUIPA | B13: Vehiculos Motorizados para el Transportes de mercancias (Categoria N) | C13: CAMIONES Y TRACTO | D13: CAMIONES | E13: VOLQUETE | F13: VOLQUETE | G13: N2 | H13: FORLAND | I13: FD250 | J13: BJ3043D8JB5-1 | K13: CHINA | L13: DIESEL | M13: 4X2 | N13: 6240 | O13: 2771 | P13: 3 | Q13: 2025 | R13: 1
... A466: LIMA | B466: Vehiculos Motorizados para el Transportes de mercancias (Categoria N) | C466: CAMIONES Y TRACTO | D466: CAMIONES | E466: CHASIS CABINADO | F466: CISTERNA | G466: N3 | H466: FOTON | I466: BJ3259DLPKE-A1 | J466: BJ3259DLPKE-A1 | K466: CHINA | L466: DIESEL | M466: 6X4 | N466: 41000 | O466: 11800 | P466: 2 | Q466: 2025 | R466: 2
A467: LIMA | B467: Vehiculos Motorizados para el Transportes de mercancias (Categoria N) | C467: CAMIONES Y TRACTO | D467: CAMIONES | E467: CHASIS CABINADO | F467: CISTERNA | G467: N3 | H467: HOWO | I467: ZZ1168F4715E1 | J467: 2023 | K467: CHINA | L467: DIESEL | M467: 4X2 | N467: 12200 | O467: 4460 | P467: 2 | Q467: 2023 | R467: 1
A468: LIMA | B468: Vehiculos Motorizados para el Transportes de mercancias (Categoria N) | C468: CAMIONES Y TRACTO | D468: CAMIONES | E468: CHASIS CABINADO | F468: CISTERNA | G468: N3 | H468: MERCEDES BENZ | I468: AXOR 3131 | J468: AXOR 3131/48 | K468: BRAZIL | L468: DIESEL | M468: 6X4 | N468: 33500 | O468: 7201 | P468: 2 | Q468: 2025 | R468: 4
A469: LIMA | B469: Vehiculos Motorizados para el Transportes de mercancias (Categoria N) | C469: CAMIONES Y TRACTO | D469: CAMIONES | E469: CHASIS CABINADO | F469: CISTERNA | G469: N3 | H469: MERCEDES BENZ | I469: AROCS 4851K | J469: AROCS 4851K | K469: GERMANY | L469: DIESEL | M469: 8X4 | N469: 48000 | O469: 12800 | P469: 2 | Q469: 2025 | R469: 1
A470: LIMA | B470: Vehiculos Motorizados para el Transportes de mercancias (Categoria N) | C470: CAMIONES Y TRACTO | D470: CAMIONES | E470: CHASIS CABINADO | F470: CISTERNA | G470: N3 | H470: MERCEDES BENZ | I470: AROCS 4851K | J470: AROCS 4851K TRC | K470: GERMANY | L470: DIESEL | M470: 8X4 | N470: 48000 | O470: 12800 | P470: 2 | Q470: 2025 | R470: 5
A471: LIMA | B471: Vehiculos Motorizados para el Transportes de mercancias (Categoria N) | C471: CAMIONES Y TRACTO | D471: CAMIONES | E471: CHASIS CABINADO | F471: CISTERNA | G471: N3 | H471: SHACMAN | I471: SX1258MR564C | J471: SX1258MR564C | K471: CHINA | L471: DIESEL | M471: 6X4 | N471: 35000 | O471: 8900 | P471: 2 | Q471: 2024 | R471: 1
A472: LIMA | B472: Vehiculos Motorizados para el Transportes de mercancias (Categoria N) | C472: CAMIONES Y TRACTO | D472: CAMIONES | E472: CHASIS CABINADO | F472: CISTERNA | G472: N3 | H472: SHACMAN | I472: SX1258MV564C | J472: NO CORRESPONDE | K472: CHINA | L472: DIESEL | M472: 6X4 | N472: 33500 | O472: 10800 | P472: 2 | Q472: 2024 | R472: 3
A473: LIMA | B473: Vehiculos Motorizados para el Transportes de mercancias (Categoria N) | C473: CAMIONES Y TRACTO | D473: CAMIONES | E473: CHASIS CABINADO | F473: CISTERNA | G473: N3 | H473: VOLKSWAGEN | I473: 17.260 DC ROBUST MAN E5 | J473: CHASIS CABINADO | K473: BRAZIL | L473: DIESEL | M473: 4X2 | N473: 17100 | O473: 6871 | P473: 2 | Q473: 2025 | R473: 1
A474: LIMA | B474: Vehiculos Motorizados para el Transportes de mercancias (Categoria N) | C474: CAMIONES Y TRACTO | D474: CAMIONES | E474: CHASIS CABINADO | F474: CISTERNA | G474: N3 | H474: VOLKSWAGEN | I474: 31.390 DC CUMMINS E5 | J474: CHASIS CABINADO | K474: BRAZIL | L474: DIESEL | M474: 6X4 | N474: 30500 | O474: 8900 | P474: 2 | Q474: 2025 | R474: 1
A475: LIMA | B475: Vehiculos Motorizados para el Transportes de mercancias (Categoria N) | C475: CAMIONES Y TRACTO | D475: CAMIONES | E475: CHASIS CABINADO | F475: CISTERNA | G475: N3 | H475: VOLVO | I475: FMX 6X4 R | J475: FMX 6X4 R | K475: BRAZIL | L475: DIESEL | M475: 6X4 | N475: 36000 | O475: 12800 | P475: 2 | Q475: 2025 | R475: 1
A476: LIMA | B476: Vehiculos Motorizados para el Transportes de mercancias (Categoria N) | C476: CAMIONES Y TRACTO | D476: CAMIONES | E476: CHASIS CABINADO | F476: CISTERNA | G476: N3 | H476: VOLVO | I476: FMX 6X4 R | J476: FMX 6X4 R | K476: BRAZIL | L476: DIESEL | M476: 6X4 | N476: 44000 | O476: 12800 | P476: 2 | Q476: 2025 | R476: 1
A477: LIMA | B477: Vehiculos Motorizados para el Transportes de mercancias (Categoria N) | C477: CAMIONES Y TRACTO | D477: CAMIONES | E477: CHASIS CABINADO | F477: CISTERNA | G477: N3 | H477: VOLVO | I477: VM 6X4 R | J477: VM 6X4 R | K477: BRAZIL | L477: DIESEL | M477: 6X4 | N477: 34000 | O477: 7700 | P477: 2 | Q477: 2025 | R477: 3
A478: LIMA | B478: Vehiculos Motorizados para el Transportes de mercancias (Categoria N) | C478: CAMIONES Y TRACTO | D478: CAMIONES | E478: CHASIS CABINADO | F478: CISTERNA COMBUSTIBLES | G478: N2 | H478: HYUNDAI | I478: EX8 | J478: STANDARD | K478: KOREA, REPUBLIC OF | L478: DIESEL | M478: 4X2 | N478: 7800 | O478: 2891 | P478: 3 | Q478: 2024 | R478: 1
A479: LIMA | B479: Vehiculos Motorizados para el Transportes de mercancias (Categoria N) | C479: CAMIONES Y TRACTO | D479: CAMIONES | E479: CHASIS CABINADO | F479: CISTERNA COMBUSTIBLES | G479: N2 | H479: HYUNDAI | I479: EX11 | J479: TDI CRDI EURO IV | K479: KOREA, REPUBLIC OF | L479: DIESEL | M479: 4X2 | N479: 10300 | O479: 3933 | P479: 3 | Q479: 2023 | R479: 1
... A542: LIMA | B542: Vehiculos Motorizados para el Transportes de mercancias (Categoria N) | C542: CAMIONES Y TRACTO | D542: CAMIONES | E542: CHASIS CABINADO | F542: FURGON | G542: N3 | H542: HINO | I542: GH | J542: LARGO-SEMI FULL | K542: JAPAN | L542: DIESEL | M542: 4X2 | N542: 17800 | O542: 7684 | P542: 3 | Q542: 2025 | R542: 1
A543: LIMA | B543: Vehiculos Motorizados para el Transportes de mercancias (Categoria N) | C543: CAMIONES Y TRACTO | D543: CAMIONES | E543: CHASIS CABINADO | F543: FURGON | G543: N3 | H543: HOWO | I543: ZZ1168F5215E1 | J543: 2023 | K543: CHINA | L543: DIESEL | M543: 4X2 | N543: 16500 | O543: 4460 | P543: 2 | Q543: 2023 | R543: 1
A544: LIMA | B544: Vehiculos Motorizados para el Transportes de mercancias (Categoria N) | C544: CAMIONES Y TRACTO | D544: CAMIONES | E544: CHASIS CABINADO | F544: FURGON | G544: N3 | H544: ISUZU | I544: FTR34UL-PDPEN | J544: 10TON | K544: JAPAN | L544: DIESEL | M544: 4X2 | N544: 15295 | O544: 7790 | P544: 3 | Q544: 2024 | R544: 1
A545: LIMA | B545: Vehiculos Motorizados para el Transportes de mercancias (Categoria N) | C545: CAMIONES Y TRACTO | D545: CAMIONES | E545: CHASIS CABINADO | F545: FURGON | G545: N3 | H545: ISUZU | I545: FTR34UL-PDPEN | J545: 10TON | K545: JAPAN | L545: DIESEL | M545: 4X2 | N545: 15295 | O545: 7790 | P545: 3 | Q545: 2025 | R545: 6
A546: LIMA | B546: Vehiculos Motorizados para el Transportes de mercancias (Categoria N) | C546: CAMIONES Y TRACTO | D546: CAMIONES | E546: CHASIS CABINADO | F546: FURGON | G546: N3 | H546: ISUZU | I546: FVR34UL-QDPES | J546: 13TON | K546: JAPAN | L546: DIESEL | M546: 4X2 | N546: 18630 | O546: 7790 | P546: 3 | Q546: 2025 | R546: 1
A547: LIMA | B547: Vehiculos Motorizados para el Transportes de mercancias (Categoria N) | C547: CAMIONES Y TRACTO | D547: CAMIONES | E547: CHASIS CABINADO | F547: FURGON | G547: N3 | H547: JAC | I547: HFC1083KN | J547: SD800 VIP CHC 9.0T CRDI EIV | K547: CHINA | L547: DIESEL | M547: 4X2 | N547: 12590 | O547: 3760 | P547: 3 | Q547: 2025 | R547: 1
A548: LIMA | B548: Vehiculos Motorizados para el Transportes de mercancias (Categoria N) | C548: CAMIONES Y TRACTO | D548: CAMIONES | E548: CHASIS CABINADO | F548: FURGON | G548: N3 | H548: JAC | I548: HFC1161KR1ZT | J548: HFC1161KR 4X2 CHC 14.8T CRDI 285HP | K548: CHINA | L548: DIESEL | M548: 4X2 | N548: 20500 | O548: 6700 | P548: 3 | Q548: 2025 | R548: 1
A549: LIMA | B549: Vehiculos Motorizados para el Transportes de mercancias (Categoria N) | C549: CAMIONES Y TRACTO | D549: CAMIONES | E549: CHASIS CABINADO | F549: FURGON | G549: N3 | H549: MERCEDES BENZ | I549: ATEGO 1419 | J549: ATEGO 1419/54 | K549: BRAZIL | L549: DIESEL | M549: 4X2 | N549: 14300 | O549: 4801 | P549: 2 | Q549: 2025 | R549: 2
A550: LIMA | B550: Vehiculos Motorizados para el Transportes de mercancias (Categoria N) | C550: CAMIONES Y TRACTO | D550: CAMIONES | E550: CHASIS CABINADO | F550: FURGON | G550: N3 | H550: MERCEDES BENZ | I550: ATEGO 2430 | J550: ATEGO 2430/54 | K550: BRAZIL | L550: DIESEL | M550: 6X2 | N550: 24500 | O550: 7200 | P550: 2 | Q550: 2025 | R550: 2
A551: LIMA | B551: Vehiculos Motorizados para el Transportes de mercancias (Categoria N) | C551: CAMIONES Y TRACTO | D551: CAMIONES | E551: CHASIS CABINADO | F551: FURGON | G551: N3 | H551: SCANIA | I551: P320 B6X2 | J551: P320B6X2NA | K551: BRAZIL | L551: DIESEL | M551: 6X2 | N551: 26500 | O551: 9300 | P551: 2 | Q551: 2025 | R551: 4
A552: LIMA | B552: Vehiculos Motorizados para el Transportes de mercancias (Categoria N) | C552: CAMIONES Y TRACTO | D552: CAMIONES | E552: CHASIS CABINADO | F552: FURGON | G552: N3 | H552: UD | I552: CRONER PKE | J552: CRONER PKE | K552: THAILAND | L552: DIESEL | M552: 4X2 | N552: 18500 | O552: 7700 | P552: 3 | Q552: 2025 | R552: 2
A553: LIMA | B553: Vehiculos Motorizados para el Transportes de mercancias (Categoria N) | C553: CAMIONES Y TRACTO | D553: CAMIONES | E553: CHASIS CABINADO | F553: FURGON | G553: N3 | H553: VOLVO | I553: VM 4X2 R | J553: VM 4X2 R | K553: BRAZIL | L553: DIESEL | M553: 4X2 | N553: 17700 | O553: 7700 | P553: 2 | Q553: 2025 | R553: 2
A554: LIMA | B554: Vehiculos Motorizados para el Transportes de mercancias (Categoria N) | C554: CAMIONES Y TRACTO | D554: CAMIONES | E554: CHASIS CABINADO | F554: FURGON | G554: N3 | H554: VOLVO | I554: VM 6X2 R | J554: VM 6X2 R | K554: BRAZIL | L554: DIESEL | M554: 6X2 | N554: 24700 | O554: 7700 | P554: 2 | Q554: 2025 | R554: 7
...
